<?xml version='1.0'?>

<robot name="garbage_boat" xmlns:xacro="http://www.ros.org/wiki/xacro">
  <xacro:include filename="$(find garbage_boat)/urdf/common_macros.xacro" />
  <xacro:include filename="$(find garbage_boat)/urdf/garbage_boat.urdf.gazebo" />

 <!-- <xacro:property name="density" value="1" /> -->

  <material name="COLOR">
   <color rgba="1 1 1 1"/>
 </material>
  <link name='base_link'>
    <pose>0 0 0.1 0 0 0</pose>
    <visual name='chassis_visual'>
      <origin xyz="0 0 -0.1" rpy="0 0 ${pi/2}"/>
      <geometry>
        <mesh filename="package://garbage_boat/meshes/RobotBatPOrsjekt_v4_v5.stl" scale="0.001 0.001 0.001"/>
       <!-- <box size="1 0.3 0.1"/> -->
      </geometry>
      <material name="COLOR"/>
    </visual>
    <collision>
      <origin xyz="0 0 0.07" rpy="0 0 0"/>
      <geometry>
        <!-- <box size="1 0.4 0.1"/> -->
        <box size="1 0.3 0.1"/>
      </geometry>
    </collision>
    <inertial>
      <mass value="10"/>
      <inertia ixx="0.1075" ixy="0.0" ixz="0.0" iyy="10.0008" iyz="0.0" izz="10.0075"/>
    </inertial>
</link>

  <link name='left_thruster'>
    <visual>
      <geometry>
       <cylinder length="0.07" radius="0.03"/>
     </geometry>
     <!-- <origin rpy="1.5707963 0 0" xyz="0.15 0.465 -0.03"/> -->
     <origin rpy="${pi/2} 0 ${pi/2}" xyz="-0.465 0.15 -0.03"/>
   </visual>
  </link>

  <link name='right_thruster'>
    <visual>
      <geometry>
       <cylinder length="0.07" radius="0.03"/>
     </geometry>
     <!-- <origin rpy="1.5707963 0 0" xyz="-0.15 0.465 -0.03"/> -->
     <origin rpy="${pi/2} 0 ${pi/2}" xyz="-0.465 -0.15 -0.03"/>
   </visual>
  </link>

  <joint name="base_to_left_thruster" type="fixed">
    <parent link="base_link"/>
    <child link="left_thruster"/>
  </joint>

  <joint name="base_to_right_thruster" type="fixed">
    <parent link="base_link"/>
    <child link="right_thruster"/>
  </joint>

  <joint name="left_front_wheel_j" type="continuous">
    <origin xyz="0.20 0.20 0" rpy="${-pi/2} 0 0"/>
    <parent link="base_link"/>
    <child link="lf_wheel"/>
    <axis xyz="0 0 1" rpy="0 0 0"/>
    <limit effort="100" velocity="100"/>
  </joint>

  <xacro:link_wheel link_name="lf_wheel">
    <!-- collison -->
    <origin xyz="0 0 0" rpy="0 0 0"/>
    <!-- inertia -->
    <origin xyz="0 0 0" rpy="0 0 0"/>
  </xacro:link_wheel>

  <joint name="right_front_wheel_j" type="continuous">
    <origin xyz="0.20 -0.20 0" rpy="${-pi/2} 0 0"/>
    <parent link="base_link"/>
    <child link="rf_wheel"/>
    <axis xyz="0 0 1" rpy="0 0 0"/>
    <limit effort="100" velocity="100"/>
  </joint>

  <xacro:link_wheel link_name="rf_wheel">
    <!-- collison -->
    <origin xyz="0 0 0" rpy="0 0 0"/>
    <!-- inertia -->
    <origin xyz="0 0 0" rpy="0 0 0"/>
  </xacro:link_wheel>


  <joint name="left_rear_wheel_j" type="continuous">
    <origin xyz="-0.20 0.20 0" rpy="${-pi/2} 0 0"/>
    <parent link="base_link"/>
    <child link="lr_wheel"/>
    <axis xyz="0 0 1" rpy="0 0 0"/>
    <limit effort="100" velocity="100"/>
  </joint>

  <xacro:link_wheel link_name="lr_wheel">
    <!-- collison -->
    <origin xyz="0 0 0" rpy="0 0 0"/>
    <!-- inertia -->
    <origin xyz="0 0 0" rpy="0 0 0"/>
  </xacro:link_wheel>

  <joint name="right_rear_wheel_j" type="continuous">
    <origin xyz="-0.20 -0.20 0" rpy="${-pi/2} 0 0"/>
    <parent link="base_link"/>
    <child link="rr_wheel"/>
    <axis xyz="0 0 1" rpy="0 0 0"/>
    <limit effort="100" velocity="100"/>
  </joint>

  <xacro:link_wheel link_name="rr_wheel">
    <!-- collison -->
    <origin xyz="0 0 0" rpy="0 0 0"/>
    <!-- inertia -->
    <origin xyz="0 0 0" rpy="0 0 0"/>
  </xacro:link_wheel>

</robot>
